<?xml version="1.0" ?>
<!-- =================================================================================== -->
<!-- |    This document was autogenerated by xacro from my_four_dof_arm.xacro          | -->
<!-- |    EDITING THIS FILE BY HAND IS NOT RECOMMENDED                                 | -->
<!-- =================================================================================== -->
<robot name="stackit_robot" xmlns:xacro="http://www.ros.org/wiki/xacro">
  <material name="white">
    <color rgba="0.87 0.90 0.87 1.0"/>
  </material>
  <material name="black">
    <color rgba="0.0 0.0 0.0 1.0"/>
  </material>
  <material name="green">
    <color rgba="0.22 0.32 0.14 1.0"/>
  </material>
  <link name="base_link"/>
  <link name="arm_base_link">
    <visual>
      <geometry>
        <box size="0.5 0.5 0.001"/>
      </geometry>
      <material name="white"/>
    </visual>
  </link>
  <joint name="arm_base_joint" type="fixed">
    <origin xyz="0 0 0"/>
    <parent link="base_link"/>
    <child link="arm_base_link"/>
  </joint>
  <!-- shoulder pan joint -->
  <joint name="base_pan_servo_joint" type="fixed">
    <origin rpy="0 0 -1.570795" xyz="0 0 0.019"/>
    <parent link="arm_base_link"/>
    <child link="base_pan_servo_link"/>
  </joint>
  <link name="base_pan_servo_link">
    <visual>
      <origin rpy="0 0 0" xyz=" 0 0 0 "/>
      <geometry>
        <mesh filename="package://stackit_robot_description/meshes/AX-12A.stl" scale="0.001 0.001 0.001"/>
      </geometry>
      <material name="black"/>
    </visual>
    <collision>
      <origin rpy="0 0 0" xyz="0.0 -0.0135 0.0"/>
      <geometry>
        <box size="0.032 0.05 0.038"/>
      </geometry>
    </collision>
  </link>
  <joint name="base_pan_joint" type="revolute">
    <origin rpy="1.570795 0 1.570795" xyz="0 0 0.021"/>
    <axis xyz="0 1 0"/>
    <limit effort="30" lower="-1.571" upper="1.571" velocity="1.571"/>
    <parent link="base_pan_servo_link"/>
    <child link="base_pan_link"/>
  </joint>
  <link name="base_pan_link">
    <visual>
      <origin rpy="0 0 0" xyz=" 0 0 0 "/>
      <geometry>
        <mesh filename="package://stackit_robot_description/meshes/FP04-F3.stl" scale="0.001 0.001 0.001"/>
      </geometry>
      <material name="white"/>
    </visual>
    <collision>
      <origin rpy="0 0 0" xyz="0.0 0.0045 0"/>
      <geometry>
        <box size="0.025 0.009 0.0382"/>
      </geometry>
    </collision>
  </link>
  <!-- shoulder lift joint -->
  <joint name="base_lift_servo_joint" type="fixed">
    <origin rpy="0 3.14159 0" xyz="0 0.0415 0"/>
    <parent link="base_pan_link"/>
    <child link="base_lift_servo_link"/>
  </joint>
  <link name="base_lift_servo_link">
    <visual>
      <origin rpy="0 0 0" xyz=" 0 0 0 "/>
      <geometry>
        <mesh filename="package://stackit_robot_description/meshes/AX-12A.stl" scale="0.001 0.001 0.001"/>
      </geometry>
      <material name="black"/>
    </visual>
    <collision>
      <origin rpy="0 0 0" xyz="0.0 -0.0135 0.0"/>
      <geometry>
        <box size="0.032 0.05 0.038"/>
      </geometry>
    </collision>
  </link>
  <joint name="base_lift_joint" type="revolute">
    <origin rpy="-1.570795 -1.570795 0" xyz="0 0 0"/>
    <axis xyz="1 0 0"/>
    <limit effort="30" lower="-2.617" upper="2.617" velocity="1.571"/>
    <parent link="base_lift_servo_link"/>
    <child link="base_lift_link"/>
  </joint>
  <link name="base_lift_link">
    <visual>
      <origin rpy="0 0 0" xyz=" 0 0 0 "/>
      <geometry>
        <mesh filename="package://stackit_robot_description/meshes/FP04-F4.stl" scale="0.001 0.001 0.001"/>
      </geometry>
      <material name="white"/>
    </visual>
    <collision>
      <origin rpy="0 0 0" xyz="0.0 0.0 0.0205"/>
      <geometry>
        <box size="0.048 0.029 0.063"/>
      </geometry>
    </collision>
  </link>
  <joint name="arm_shoulder_F3_0_joint" type="fixed">
    <origin rpy="1.570795 0 -1.570795" xyz="0 0 0.052"/>
    <parent link="base_lift_link"/>
    <child link="arm_shoulder_F3_0_link"/>
  </joint>
  <link name="arm_shoulder_F3_0_link">
    <visual>
      <origin rpy="0 0 0" xyz=" 0 0 0 "/>
      <geometry>
        <mesh filename="package://stackit_robot_description/meshes/FP04-F3.stl" scale="0.001 0.001 0.001"/>
      </geometry>
      <material name="white"/>
    </visual>
    <collision>
      <origin rpy="0 0 0" xyz="0.0 0.0045 0"/>
      <geometry>
        <box size="0.025 0.009 0.0382"/>
      </geometry>
    </collision>
  </link>
  <!-- elbow joint -->
  <joint name="elbow_flex_servo_joint" type="fixed">
    <origin rpy="0 3.14159 0" xyz="0 0.0415 0"/>
    <parent link="arm_shoulder_F3_0_link"/>
    <child link="elbow_flex_servo_link"/>
  </joint>
  <link name="elbow_flex_servo_link">
    <visual>
      <origin rpy="0 0 0" xyz=" 0 0 0 "/>
      <geometry>
        <mesh filename="package://stackit_robot_description/meshes/AX-12A.stl" scale="0.001 0.001 0.001"/>
      </geometry>
      <material name="black"/>
    </visual>
    <collision>
      <origin rpy="0 0 0" xyz="0.0 -0.0135 0.0"/>
      <geometry>
        <box size="0.032 0.05 0.038"/>
      </geometry>
    </collision>
  </link>
  <joint name="elbow_flex_joint" type="revolute">
    <origin rpy="-1.570795 -1.570795 0" xyz="0 0 0"/>
    <axis xyz="1 0 0"/>
    <limit effort="30" lower="0.0" upper="2.617" velocity="1.571"/>
    <parent link="elbow_flex_servo_link"/>
    <child link="elbow_flex_link"/>
  </joint>
  <link name="elbow_flex_link">
    <visual>
      <origin rpy="0 0 0" xyz=" 0 0 0 "/>
      <geometry>
        <mesh filename="package://stackit_robot_description/meshes/FP04-F4.stl" scale="0.001 0.001 0.001"/>
      </geometry>
      <material name="white"/>
    </visual>
    <collision>
      <origin rpy="0 0 0" xyz="0.0 0.0 0.0205"/>
      <geometry>
        <box size="0.048 0.029 0.063"/>
      </geometry>
    </collision>
  </link>
  <joint name="elbow_F3_0_joint" type="fixed">
    <origin rpy="1.570795 0 -1.570795" xyz="0 0 0.052"/>
    <parent link="elbow_flex_link"/>
    <child link="elbow_F3_0_link"/>
  </joint>
  <link name="elbow_F3_0_link">
    <visual>
      <origin rpy="0 0 0" xyz=" 0 0 0 "/>
      <geometry>
        <mesh filename="package://stackit_robot_description/meshes/FP04-F3.stl" scale="0.001 0.001 0.001"/>
      </geometry>
      <material name="white"/>
    </visual>
    <collision>
      <origin rpy="0 0 0" xyz="0.0 0.0045 0"/>
      <geometry>
        <box size="0.025 0.009 0.0382"/>
      </geometry>
    </collision>
  </link>
  <!-- wrist joint -->
  <joint name="wrist_flex_servo_joint" type="fixed">
    <origin rpy="0 3.14159 0" xyz="0 0.0415 0"/>
    <parent link="elbow_F3_0_link"/>
    <child link="wrist_flex_servo_link"/>
  </joint>
  <link name="wrist_flex_servo_link">
    <visual>
      <origin rpy="0 0 0" xyz=" 0 0 0 "/>
      <geometry>
        <mesh filename="package://stackit_robot_description/meshes/AX-12A.stl" scale="0.001 0.001 0.001"/>
      </geometry>
      <material name="black"/>
    </visual>
    <collision>
      <origin rpy="0 0 0" xyz="0.0 -0.0135 0.0"/>
      <geometry>
        <box size="0.032 0.05 0.038"/>
      </geometry>
    </collision>
  </link>
  <joint name="wrist_flex_joint" type="revolute">
    <origin rpy="-1.570795 -1.570795 0" xyz="0 0 0"/>
    <axis xyz="1 0 0"/>
    <limit effort="30" lower="-1.745" upper="1.745" velocity="1.571"/>
    <parent link="wrist_flex_servo_link"/>
    <child link="wrist_flex_link"/>
  </joint>
  <link name="wrist_flex_link">
    <visual>
      <origin rpy="0 0 0" xyz=" 0 0 0 "/>
      <geometry>
        <mesh filename="package://stackit_robot_description/meshes/FP04-F2.stl" scale="0.001 0.001 0.001"/>
      </geometry>
      <material name="white"/>
    </visual>
    <collision>
      <origin rpy="0 0 0" xyz="0.0 0.0 0.00775"/>
      <geometry>
        <box size="0.0485 0.025 0.0375"/>
      </geometry>
    </collision>
  </link>
  <joint name="wrist_F2_0_joint" type="fixed">
    <origin rpy="0 3.14159 1.570795" xyz="0 0 0.052"/>
    <parent link="wrist_flex_link"/>
    <child link="wrist_F2_0_link"/>
  </joint>
  <link name="wrist_F2_0_link">
    <visual>
      <origin rpy="0 0 0" xyz=" 0 0 0 "/>
      <geometry>
        <mesh filename="package://stackit_robot_description/meshes/FP04-F2.stl" scale="0.001 0.001 0.001"/>
      </geometry>
      <material name="white"/>
    </visual>
    <collision>
      <origin rpy="0 0 0" xyz="0.0 0.0 0.00775"/>
      <geometry>
        <box size="0.0485 0.025 0.0375"/>
      </geometry>
    </collision>
  </link>
  <!-- dummy joint -->
  <link name="dummy_a_link"/>
  <joint name="dummy_a_joint" type="revolute">
    <parent link="wrist_F2_0_link"/>
    <child link="dummy_a_link"/>
    <origin rpy="3.14159 0 0" xyz="0.0225 0 0"/>
    <axis xyz="1 0 0"/>
    <limit effort="30" lower="-1.571" upper="1.571" velocity="1.571"/>
  </joint>
  <link name="dummy_b_link">
    <visual>
      <geometry>
        <box size="0.01 0.01 0.01"/>
      </geometry>
      <material name="green"/>
    </visual>
  </link>
  <joint name="dummy_b_joint" type="fixed">
    <parent link="dummy_a_link"/>
    <child link="dummy_b_link"/>
    <origin rpy="0 0 0" xyz="0 0 0"/>
    <axis xyz="0 0 0"/>
  </joint>
</robot>

